Workbook

Sheet Tracker
A1: Tab | B1: Wave 0 status (Generic) | C1: Wave 1 status (Generic) | D1: Wave 3 status (Generic) | E1: Wave 4 status (DTC-IEX) | F1: Wave 5 status (EB & DG) | G1: Wave 6 status (Disability) | H1: Wave 7 status (BA & EBH) | I1: Wave 8 status (DI Claims) | J1: Wave 2 status (IM) | K1: Due Date | M1: Notes
A2: Organization Settings | B2: DONE FOR ALL
A3: Locations | B3: DONE | C3: DONE | D3: DONE for all
A4: Telephony Config | B4: DONE | C4: DONE | D4: All done unless Amelia_Hugo_1_UAT is needed | L4: Mike
A5: Users | B5: n/a | C5: DONE | D5: DONE | E5: DONE | F5: DONE | G5: DONE | H5: DONE | I5: DONE | J5: DONE | L5: Mike | M5: Tracked in alternate spreadsheet
A6: Phones Prod | B6: n/a | C6: DONE | D6: DONE | E6: DONE | F6: DONE | G6: DONE | H6: DONE | I6: DONE | J6: DONE | L6: Mike | M6: Tracked in alternate spreadsheet
A7: Custom Roles | B7: n/a | C7: DONE | D7: DONE | E7: DONE | F7: remaining custom roles will be imported with users for each wave | M7: William, James TTech, Josh from Verint / Robert GLIC
A8: DID-TFN Log | B8: DONE | C8: DONE | D8: DONE | E8: DONE | F8: DONE | G8: by go live 10/16 | H8: by go live 10/9 | I8: by go live 10/23 | J8: by go live 10/30 | K8: 45574
A9: Groups for VM - Nebula | B9: DONE FOR ALL
A10: Groups for VM - Supernova | B10: n/a | C10: DONE manually | D10: DONE | E10: DONE | F10: n/a | G10: n/a | H10: DONE | I10: DONE | J10: DONE
A11: Groups - Skill Expressions | B11: DONE | C11: DONE | D11: DONE | E11: DONE | F11: DONE | G11: DONE | H11: DONE | I11: DONE | J11: DONE
A12: External Contacts | B12: DONE FOR ALL
A13: Queues | B13: DONE | C13: DONE | D13: DONE
A14: Schedules | B14: DONE FOR ALL
A15: Schedule Groups | B15: DONE | C15: DONE | D15: DONE FOR ALL
A16: Call Routing | B16: DONE | C16: DONE 8/21
A17: Skills & Languages | B17: DONE | C17: DONE | D17: DONE | E17: DONE | F17: DONE | G17: DONE | H17: DONE | I17: DONE | J17: DONE
A18: Analytics | B18: TO BE HANDLED VIA A3S
A19: Agent Utilization | B19: DONE FOR ALL
A20: Agent Scripts | B20: n/a | C20: DONE | D20: n/a | E20: DONE | F20: n/a | G20: n/a | H20: n/a | I20: n/a | J20: n/a
A21: Status Codes | B21: DONE FOR ALL
A22: Divisions | B22: DONE FOR ALL
A23: Interaction Flows | B23: DONE | C23: DONE | D23: DONE | E23: DONE | F23: DONE | G23: DONE | H23: DONE | I23: DONE | J23: DONE | L23: Mike
A24: Flow Outcomes | B24: DONE FOR ALL
A25: Flow Milestones | B25: DONE FOR ALL
A26: ANI BLOCK LIST | B26: DONE FOR ALL
A27: Data Tables | B27: DONE | C27: DONE | D27: DONE | E27: DONE | F27: DONE | G27: DONE | H27: DONE | I27: DONE | J27: DONE
A28: Data Actions | B28: DONE | C28: DONE | D28: DONE | E28: DONE | F28: DONE | G28: DONE | H28: DONE | I28: DONE | J28: DONE | L28: Mike | M28: doing when move to prod
A29: Integrations | B29: DONE FOR ALL
A30: Recording Policy | B30: n/a | C30: DONE | D30: DONE | E30: DONE | F30: DONE | G30: Needs to be re-configured | K30: 45569 | L30: Mike | M30: has info needed
A32: UAT IT start | F32: 45530 | G32: 45538 | H32: 45530 | I32: 45544 | J32: 45551
A33: UAT Business start | F33: 45544 | G33: 45546 | H33: 45553 | I33: 45558 | J33: 45565
A34: Go live date | D34: 45539 | E34: 45546 | F34: 45560 | G34: 45581 | H34: 45574 | I34: 45588 | J34: 45595

Sheet Organization Settings
A1: Org Settings | C1: About organization settings - Genesys Cloud Resource Center (mypurecloud.com)
A2: Setting Name | B2: Description | C2: Setting
A3: Company Name | B3: Specifies the full name of your organization. Edit the Company Name to change the organization name displayed on the Login screen, on the browser tab, and on each user’s Mini Cards.
A4: Short Name | B4: Specifies the short name of your organization. Use this name to log in to the organization. You cannot edit the short name.
A5: Organization ID | B5: Specifies an ID number that is unique to each organization. A Genesys Cloud Support representative may ask for this number when troubleshooting an issue.
A6: GLOBAL SETTINGS
A7: Location Detection Available (On / Off) | B7: When ON, users' geolocation is displayed if they choose to share their current location. OFF, geolocation is disabled for everyone. | C7: On
A8: Default Language | B8: The language used for notification emails such as new user invites and password resets. | C8: English
A9: Default Country Code | B9: The default country code that is used when adding certain phone numbers. | C9: United States
A10: Issue Reporting Email Address | B10: Distribution email address for "Report an Issue" submission. Only one email address can be specified. Otherwise, emails will go to all users with "admin" role.
A11: ONBOARDING PEOPLE
A12: Auto Invite (On / Off) | B12: Send email invites automatically when users are added. | C12: off
A13: Open Admission (On / Off) | B13: People with the email domains below can add themselves to this organization. Note - disabling will invalidate your organization's sign up link. If it is re-enabled, it will create a new link. | C13: off
A14: Allowed Email Domain(s) | B14: Enter a list of domains (one per line); only people with these email domains will be allowed to sign up with this link.
A15: TELEPHONY
A16: Free Seating (On / Off) | B16: Toggle whether offline agents' assigned stations are freely available for use. | C16: off
A17: Voicemail PIN (On / Off) | B17: Toggle whether a PIN is always required for accessing voicemail, even from phones associated with the given mailbox. | C17: off
A18: Timeout Seconds | B18: The number of seconds to alert the user before the call rolls over to voicemail. | C18: 12
A19: Maximum Voicemail Length | B19: Set the maximum allowed length of a voicemail in whole minutes. | C19: 5
A20: Default TTS Engine | B20: Default TTS Engine used for flows and other cases | C20: Genesys TTS
A21: Language Overides | B21: Change TTS Engine based on interaction's language
A22: CONTACT CENTER
A23: Enforce Widget Deployments (On / Off) | B23: When on, chat is only allowed via widget deployments. When off, chats can use the legacy web chat configuration. WARNING: Only turn on this toggle after you have successfully implemented and verified widget deployments. | C23: off
A24: Strip Skills on Blind Transfer (On / Off) | B24: When on, all skills, except language(s), will be removed from the ACD interaction when blind transferred across queues. | C24: off
A25: Routing Includes Agent Presence (On / Off) | B25: When enabled, all queue routing methods will use changes in agent presence to reset the ACD routing score. This will result in interactions being delivered to the agent who has been sitting in idle/available the longest intra-day. By default, interactions are routing based on the 'time since last interaction'. | C25: off
A26: Renew Presence on Reconnect | B26: When enabled, presence status will be renewed when reconnecting to Genesys Cloud. | C26: off
A27: Enforce Communication Level After Call Work (ACW) | B27: When enabled, After Call Work ( ACW ) will be set at the communication level (vs. the participant level) to deliver better analytics and future enhancements. Additionally, supervisors will be able to utilize all queue-level ACW settings across all media types (including timeout and agent-requested options). | C27: off
A28: Route Email to multiple destinations | B28: Allow for inbound email to be routed simultaneously to multiple queues/flows based on the email addresses in the to, cc, and bcc fields. | C28: off
A29: Security & Compliance
A30: Sensitive Data Redaction for Payment Cards | B30: On a best effort basis, automatically redact Payment Card Industry (PCI) entities from recordings and transcripts. This capability is only available if speech or text analytics is enabled for the interaction. Note that users with elevated permissions can still access the original recording if needed | C30: off
A31: Sensitive Data Redaction for Personal Information | B31: On a best effort basis, automatically redact personal information entities from recordings and transcripts. This capability is only available if speech or text analytics is enabled for the interaction. Note that users with elevated permissions can still access the original recording if needed. | C31: off
A32: Disable Chat File Uploads (On / Off) | B32: When on, users cannot attach a file to the body of a chat. This setting applies to both internal chat and web chat. | C32: off
A33: Chat Message Retention Days (On / Off) | B33: The number of days, between 10 and 3650, to retain chat messages. | C33: 3650
A34: Maximum Interaction Data Retention Time | B34: Sets an organization-wide policy for the maximum retention of interaction data and recordings. The number of days after which all interactions and recordings will be deleted.
A35: HIPAA (On / Off) | B35: This setting is required for compliance with the Health Insurance Portability and Accountability Act (HIPAA | C35: off
A36: PCI DSS (On / Off) | B36: This setting is required for compliance with the Payment Card Industry Data Security Standard (PCI DSS) for handling payment cardholder data. | C36: off
A37: Voicemail Notifications | B37: Allow email notifications for Voicemail | C37: On
B38: Allow PII in Email Notifications | C38: For HIPAA compliant organizations PII will not be allowed in email notifications | D38: On
B39: Voicemail Transcription | C39: Enable Voicemail Transcriptions for your organization. | D39: Off
A40: Fax Notifications | B40: Allow email notifications for Fax | C40: On
...

Sheet Locations
A1: Location Information | J1: Add a location - Genesys Cloud Resource Center (mypurecloud.com) | K1: Address verified in org?
A2: Location Name | B2: Street Address | C2: Street Address 2 | D2: City | E2: State | F2: Zip Code | G2: Country | H2: Notes | I2: Emergency Number
A3: Bethlehem | B3: 6255 Sterners Way | D3: Bethlehem | E3: PA | F3: 18017 | G3: United States | I3: 14845101909 | J3: Wave 1 | K3: Yes
A4: Remote - NA | B4: 10 Hudson Yards 30th AVE | D4: New York | E4: NY | F4: 10001 | G4: United States | I4: 14845101905 | J4: Wave 1 | K4: Yes
A5: India BPO - Chennai | B5: #4 Rajiv Gandhi Salai | C5: #0506, D Block, Tidel Park | D5: Taramani | E5: Chennai | F5: 600113 | G5: India | H5: Not 100% sure the components are in the right column | I5: 14845101901 | K5: No
A6: India BPO - Gurgaon | B6: Candor InfoSec Tikri Sector 48 | C6: Complex Floor 7-9, Tower 1 | D6: Vill – Tikri, Sector – 48 | E6: Gurgaon | F6: 122001 | G6: India | H6: Not 100% sure the components are in the right column | I6: 14845101899 | K6: No
A7: Foundever - Philippines | B7: Benedicto St Commerce St, corner B. | D7: Cebu City, Cebu | E7: Philippines | I7: 14845101898 | K7: No
A8: Foundever - El Sal | B8: PQ5Q+5XX, Blvr. De Los Heroes, San Salvador 1101, El Salvador | I8: 14845101897 | K8: No

Sheet Telephony Config
A1: Telephony Information | I1: Number Plans
A2: Org | B2: Site Name | C2: Location | D2: Description | E2: Add. Number Plans | F2: Add. Outbound Route | G2: Built | I2: Name | J2: Match Type | K2: Match Criteria | L2: Classification | M2: Built Dev | N2: Built PROD
A3: glic-supernova | B3: Bethlehem | C3: Bethlehem | E3: Hugo Prod, BYOC | F3: Hugo Prod, BYOC | G3: Yes | H3: Needs BYOC Route, default route | I3: Hugo Dev | J3: e.164 Number List | K3: +16101951100 - 1104 | L3: Hugo Dev | M3: N/A | N3: N/A | O3: (n/a becuse tracked on site progress)
B4: Holmdel | C4: Holmdel | E4: Hugo Prod, BYOC | F4: Hugo Prod, BYOC | G4: Yes | H4: Needs BYOC Route, default route | I4: Hugo UAT | J4: e.164 Number List | K4: +16101952100 - 2104 | L4: Hugo UAT | M4: N/A | N4: N/A
B5: Hudson Yards | C5: Hudson Yards | E5: Hugo Prod, BYOC | F5: Hugo Prod, BYOC | G5: Yes | H5: Needs BYOC Route, default route | I5: Hugo Prod | J5: e.164 Number List | K5: +16101953100 - 3104 | L5: Hugo Prod | M5: N/A | N5: N/A
B6: Pittsfield | C6: Pittsfield | E6: Hugo Prod, BYOC | F6: Hugo Prod, BYOC | G6: Yes | H6: Needs BYOC Route, default route | I6: BYOC | J6: e.164 Number List | K6: +16101990000 - 9999 | L6: BYOC | M6: N/A | N6: N/A
B7: India BPO - Chennai | C7: India BPO - Chennai | E7: Hugo Prod, BYOC | F7: Hugo Prod, BYOC | G7: Yes | H7: Needs BYOC Route, default route | I7: Outbound Routes
B8: India BPO - Gurgaon | C8: India BPO - Gurgaon | E8: Hugo Prod, BYOC | F8: Hugo Prod, BYOC | G8: Yes | H8: Needs BYOC Route, default route | I8: Name
B9: Foundever - Philippines | C9: Foundever - Philippines | E9: Hugo Prod, BYOC | F9: Hugo Prod, BYOC | G9: Yes | H9: Needs BYOC Route
B10: Foundever - El Sal | C10: Foundever - El Sal | E10: Hugo Prod, BYOC | F10: Hugo Prod, BYOC | G10: Yes | H10: Needs BYOC Route
B11: Remote - NA | C11: Remote - NA | E11: Hugo Prod, BYOC | F11: Hugo Prod, BYOC | G11: Yes | H11: Needs Hugo route, default route
A12: glic-nebula | B12: Testing Site | C12: Testing Location | E12: Hugo Dev, Hugo UAT | F12: Hugo DEV, Hugo UAT | G12: Yes
B13: PureCloud Voice - AWS | C13: Default PCV Location | E13: Hugo Dev, Hugo UAT | F13: Hugo DEV, Hugo UAT | G13: Yes
A17: Org | B17: Base Phone Settings | C17: Relevent Information | F17: Built DEV | G17: Built Prod
A18: All | B18: WebRTC Base | F18: Yes | G18: Yes
A23: Org | B23: Trunk Config | C23: Type | D23: Enable SIP REFER | E23: Protocol | F23: Inbound - Number Plan Site | G23: Inbound - SIP Term ID | H23: Outbound - SIP Term ID | I23: SIP Servers or Proxies | J23: Caller ID # and Name | K23: Caller ID Prioritization | L23: Suppress User | M23: SIP Access Control | N23: Recording | O23: Additional Notes | P23: Built
A24: glic-supernova | B24: GDDOVSBCAPPP | C24: BYOC Generic Carrier | D24: FALSE | E24: TLS | G24: gdd-supernova.glic | H24: DDC-GenesysCloudCX1.glic.com | I24: 209.10.184.8:5061 | K24: Call Source/Site/Trunk | L24: Always | M24: 209.10.184.8 | N24: On | P24: Yes
B25: GRDOVSBCAPPP | C25: BYOC Generic Carrier | D25: FALSE | E25: TLS | G25: grd-supernova.glic | H25: DDC-GenesysCloudCX3.glic.com | I25: 209.10.184.9:5061 | K25: Call Source/Site/Trunk | L25: Always | M25: 209.10.184.9 | N25: On | P25: Yes
B26: Amelia_Hugo_1 | C26: BYOC Generic Carrier | D26: TRUE | E26: TLS | G26: use1-prod-sbc-25 | H26: use1-prod-sbc-25.sip.amelia.com | I26: use1-prod-sbc-25.sip.amelia.com:5062 | K26: Trunk | L26: Always | M26: 54.242.117.115 | N26: On | P26: Yes
B27: Amelia_Hugo_2 | C27: BYOC Generic Carrier | D27: TRUE | E27: TLS | G27: use1-prod-sbc-26 | H27: use1-prod-sbc-26.sip.amelia.com | I27: use1-prod-sbc-26.sip.amelia.com:5062 | K27: Trunk | L27: Always | M27: 3.218.217.246 | N27: On | P27: Yes
B28: Amelia_Hugo_3 | C28: BYOC Generic Carrier | D28: TRUE | E28: TLS | G28: use2-prod-sbc-25 | H28: use2-prod-sbc-25.sip.amelia.com | I28: use2-prod-sbc-25.sip.amelia.com:5062 | K28: Trunk | L28: Always | M28: 18.190.30.8 | N28: On | P28: Yes
B29: Amelia_Hugo_4 | C29: BYOC Generic Carrier | D29: TRUE | E29: TLS | G29: use2-prod-sbc-26 | H29: use2-prod-sbc-26.sip.amelia.com | I29: use2-prod-sbc-26.sip.amelia.com:5062 | K29: Trunk | L29: Always | M29: 3.17.114.33 | N29: On | P29: Yes
B30: PureCloud Voice - AWS | C30: Genesys Cloud Voice | D30: FALSE | K30: Call Source/Site/Trunk | L30: Always | N30: On | P30: Yes
A31: DR | B31: Dallas | C31: BYOC Generic Carrier | D31: FALSE | E31: TLS | G31: Guardian_DR_Dallas | K31: Call Source/Site/Trunk | L31: Always | N31: On | P31: No
B32: Richmond | C32: BYOC Generic Carrier | D32: FALSE | E32: TLS | G32: Guardian_DR_Richmond | K32: Call Source/Site/Trunk | L32: Always | N32: On | P32: No
B33: Amelia_Hugo_1 | C33: BYOC Generic Carrier | D33: TRUE | E33: TLS | G33: use1-prod-sbc-25 | H33: use1-prod-sbc-25.sip.amelia.com | I33: use1-prod-sbc-25.sip.amelia.com:5062 | K33: Trunk | L33: Always | M33: 54.242.117.115 | N33: On | P33: No
B34: Amelia_Hugo_2 | C34: BYOC Generic Carrier | D34: TRUE | E34: TLS | G34: use1-prod-sbc-26 | H34: use1-prod-sbc-26.sip.amelia.com | I34: use1-prod-sbc-26.sip.amelia.com:5062 | K34: Trunk | L34: Always | M34: 3.218.217.246 | N34: On | P34: No
B35: Amelia_Hugo_3 | C35: BYOC Generic Carrier | D35: TRUE | E35: TLS | G35: use2-prod-sbc-25 | H35: use2-prod-sbc-25.sip.amelia.com | I35: use2-prod-sbc-25.sip.amelia.com:5062 | K35: Trunk | L35: Always | M35: 18.190.30.8 | N35: On | P35: No
B36: Amelia_Hugo_4 | C36: BYOC Generic Carrier | D36: TRUE | E36: TLS | G36: use2-prod-sbc-26 | H36: use2-prod-sbc-26.sip.amelia.com | I36: use2-prod-sbc-26.sip.amelia.com:5062 | K36: Trunk | L36: Always | M36: 3.17.114.33 | N36: On | P36: No
B37: PureCloud Voice - AWS | C37: Genesys Cloud Voice | D37: FALSE | K37: Call Source/Site/Trunk | L37: Always | N37: On | P37: No
A38: glic-nebula | B38: GDDOVSBCAPPQ | C38: BYOC Generic Carrier | D38: FALSE | E38: TLS | G38: gdd-nebula.glic | H38: DDC-GenesysCloudCX2.glic.com | I38: 209.10.184.31:5061 | K38: Call Source/Site/Trunk | L38: Always | M38: 209.10.184.31 | N38: On | P38: Yes
B39: GRDOVSBCAPPQ | C39: BYOC Generic Carrier | D39: FALSE | E39: TLS | G39: Guardian_DEV_Richmond | H39: DDC-GenesysCloudCX4.glic.com | I39: 209.10.184.32:5061 | K39: Call Source/Site/Trunk | L39: Always | M39: 209.10.184.32 | N39: On | P39: Yes
B40: Amelia_Hugo_1_UAT | C40: BYOC Generic Carrier | D40: TRUE | E40: TLS | K40: Trunk | L40: Always | P40: No
B41: Amelia_Hugo_1_DEV | C41: BYOC Generic Carrier | D41: TRUE | E41: TLS | G41: use2-dev-sbc-25 | H41: use2-dev-sbc-25.sip.amelia.com | I41: use2-dev-sbc-25.sip.amelia.com:5062 | K41: Trunk | L41: Always | M41: 3.12.191.10 | N41: On | P41: Yes
B42: PureCloud Voice - AWS | C42: Genesys Cloud Voice | D42: FALSE | L42: Always | N42: On | P42: Yes
A44: Org | B44: Edge Size | C44: Edge Count | D44: Notes
A45: glic-supernova/DR | B45: r4.xlarge | C45: 2
A46: glic-nebula | B46: t3a.medium | C46: 2
A52: About telephony - Genesys Cloud Resource Center (mypurecloud.com)

Sheet Users
A1: name | B1: email | C1: phone_work | D1: extension | E1: title | F1: department | G1: email_manager | H1: location_work | I1: roles_divisions | J1: queues | K1: division | L1: skills | M1: enable auto_answer
A2: FirstName LastName | B2: Agent@email.com | C2: 15555555555 | D2: 1234 | E2: Agent | F2: Contact Center | G2: manager@email.com | H2: Reston, VA | I2: role a [division 1; division 2], role b [division 1], User [division 1; division 2], role b [division 1] | J2: Queue1, Queue2 | K2: Global | L2: ExampleSkill1:3
A5: Tracked in alternate spreadsheet

Sheet Phones Prod
A1: name | B1: base | C1: site | D1: email | E1: remoteAddress | F1: hardwareId | G1: keyLabel | H1: lineAppearanceId | I1: did | J1: extension | K1: Built | R1: Import phones - Genesys Cloud Resource Center (mypurecloud.com) | W1: Roles
A2: Conference Room 2 | B2: Polycom Trio 8800 BaseSettings | C2: Main Office | F2: xxxxxxxxxxxx | I2: 3172222222 | J2: 2222 | W2: Communicate - User
A3: Jon Doe WebRTC | B3: WebRTC Base Settings | C3: Main Office | D3: jon.doe@customer.com | W3: User
W4: Supervisor
W5: Quality Administrator
W6: Quality Evaluator
W7: WFM Admin
A8: Tracked in alternate spreadsheet | W8: SOA PAX Reporting

Sheet Phones Dev
A1: name | B1: base | C1: site | D1: email | E1: remoteAddress | F1: hardwareId | G1: keyLabel | H1: lineAppearanceId | I1: did | J1: extension | K1: Built | R1: Import phones - Genesys Cloud Resource Center (mypurecloud.com) | W1: Roles
A2: Conference Room 2 | B2: Polycom Trio 8800 BaseSettings | C2: Main Office | F2: xxxxxxxxxxxx | I2: 3172222222 | J2: 2222 | W2: Communicate - User
A3: Jon Doe WebRTC | B3: WebRTC Base Settings | C3: Main Office | D3: jon.doe@customer.com | W3: User
W4: Supervisor
W5: Quality Administrator
W6: Quality Evaluator
W7: WFM Admin
W8: SOA PAX Reporting

Sheet Role Modifications
A1: Role Modifications
A2: Role Name | B2: Description | C2: Permission modifications | D2: Built Prod | E2: Built Dev | F2: Roles and permissions overview - Genesys Cloud Resource Center (mypurecloud.com)
A3: employee
A4: Communicate - User
A5: User | C5: Remove ability to join/unjoin queues Remove ability to pause recording Remove ability to adhoc record calls
A6: Supervisor
A7: Communicate - Admin
A8: admin
A9: Master Admin
A10: Telephony Admin
A11: Developer
A12: Quality Evaluator | C12: Add ability to assign evaluations to interactions
A13: Quality Administrator
A14: Planner Admin
A15: Script Designer
A16: Genesys Cloud Voice Admin
A17: Performance Management Admin

Sheet Custom Roles
A1: Custom Role Name | B1: Description | C1: Permissions Included | D1: Built Prod | E1: Built Dev | F1: Notes / updates | H1: Products, roles, and permissions list - Genesys Cloud Resource Center (mypurecloud.com)
A2: Agent | C2: Architect / flow / Edit Architect / flow / Publish Architect / flow / View Architect / systemPrompt / All Permissions Architect / ui / View Architect / userPrompt / All Permissions authorization / grant / All Permissions authorization / role / View Directory > User > All Permissions General / Role Manager General / User Administration General / User Manager Routing / Wrap-up Codes / All Permissions Telephony / Plugin / All | D2: Yes | E2: Yes
A3: Leader | C3: Architect > All Permissions Bridge > Actions > All Permissions Directory > Group > All Permissions Directory > User > All Permissions Directory > userPassword > All Permissions externalContacts > All Permissions General > Person Administration General > Role Manager General > User Manager integrations > All Permissions Recording > All Permissions Routing > All Permissions Single Sign-on All Permissions | D3: Yes | E3: Yes
A4: WFM | D4: Yes | E4: Yes
A5: QM | D5: Yes | E5: Yes
A6: Reviewer | D6: Yes | E6: Yes
A7: Voicemail | C7: user > voicemail > Transfer Voicemail > ACD Voicemail > Delete Voicemail > ACD Voicemail > View Voicemail > Voicemail > Receive | D7: Yes | E7: Yes
A8: Agent WFM | B8: allows TTEC adapter to track > Verint | C8: integration > ariaWFMApps > view | D8: Yes | E8: Yes | F8: 8/20 Brenda: Robert confirmed via email that this role is needed w/permission provided (permission only applies to this new role)
F9: 8/27 Robert - Agents who need this role -- Wave 4: GLIC Retail, Foundever Retail Wave 5: GLIC Dental, Foundever Dental Wave 6: GLIC Group DI, Foundever Group DI Wave 7: NSC Wave 8: IM Claims Wave 2: IMCC

Sheet DID-TFN Log
B1: (Assign to Pre-IVR Call Route) | C1: (Assign to Flow's Call Route)
A2: Flow | B2: TFN(s) | C2: Dummy DID A | D2: Dummy DID B
A3: Individual Markets IVR | B3: +18004416455, +18008192468, +18002213253, +18885003467, +18003507314 | C3: 15551110002 | D3: 15552220002
A4: Individual Markets - Claimant IVR | B4: +18664524542 | C4: 15551110011 | D4: 15552220011
A5: Individual Markets - PAS IVR | B5: +18886000003, +18886004667 | C5: 15551110012 | D5: 15552220012
A6: Individual Markets - PAIA IVR | C6: 15551110013 | D6: 15552220013
A7: Dental IVR | C7: 15551110006 | D7: 15552220006
A8: Direct to Consumer IEX IVR | B8: +18666599900, +18445615600, +18882434578 | C8: 15551110003 | D8: 15552220003
A9: Employee Benefits IVR | C9: 15551110005 | D9: 15552220005
A10: Employee Benefits Hotline IVR | C10: 15551110007 | D10: 15552220007
A11: HB Recuritment IVR | C11: 15551110010 | D11: 15552220010
A12: Generic Menu IVR | C12: 15551110000 | D12: 15552220000
A13: Password Reset IVR | B13: +18664409326, +18664408924 | C13: 15551110001 | D13: 15552220001
A14: Group Disability IVR | C14: 15551110004 | D14: 15552220004
A15: Broker Admin IVR | C15: 15551110008 | D15: 15552220008
A16: postivr_routing | B16: N/A | C16: 15551110009 | D16: 15552220009
A18: DID Range Purpose | B18: DID Range | C18: Built Prod | D18: Built Dev
A19: Dummy DID A | B19: +15551110000 - +15551110099 | C19: Yes | D19: Yes
A20: Dummy DID B | B20: +15552220000 - +15552220099 | C20: Yes | D20: Yes
A21: In Use TFNs | B21: Many/discontiguous (~130) | C21: No | D21: No | E21: see Go live tracker - configured night of go live
A22: Out of Use TFNs | B22: Many/discontiguous (~470) | C22: No | D22: No | E22: see Go live tracker - configured night of go live
A23: Transfer numbers | B23: Many/discontiguous 1610199xxxx | C23: No | D23: No | E23: see Go live tracker - configured night of go live
A25: Extension Range Purpose | B25: Extension Range | C25: Built Prod | D25: Built Dev
A26: External inbound to users | B26: Get from user sheet
A27: Group for Voicemail | B27: 8000-8999 | C27: Yes | D27: Yes
A28: User extensions | B28: 30000-30500 | C28: Yes | D28: N/A
A32: Manage DID and toll-free number ranges - Genesys Cloud Resource Center (mypurecloud.com)
A33: Manage DID and toll-free number assignments - Genesys Cloud Resource Center (mypurecloud.com)

Sheet Groups
A1: Group Config | D1: About groups - Genesys Cloud Resource Center (mypurecloud.com)
A2: Group Name | B2: Admin Team | D2: About setting up groups (admins) - Genesys Cloud Resource Center (mypurecloud.com)
A3: Type | B3: Official / Social
A4: Visibility Public: Anyone can find the group. Members Only: Only members of the group can find the group. Owners Only: Only owners and members of the group can find the group. | B4: Members Only / Owners Only / Public
A5: Include Owners | B5: yes / no
A6: Enable Calls | B6: On / Off
A7: Group Phone Number / Extension | B7: <DID number in E164 format> <Extension configured on the platform>
A8: Call Route Type Broadcast: 15 randomly selected members will be called simultaneously with a maximum of 1,000 members in rotation. Sequential: Sequential routes will call members in a specified order. Rotary: Rotary routes will call members based on who has last received a call. | B8: Broadcast / Sequential / Rotary
A9: Rotate Calls | B9: Every T seconds | C9: T =
A10: Stop Ringing | B10: After N rotations | C10: N =
A11: Overflow | B11: Off / On
A12: Overflow / Back-up Contact Note: Overflow calls will always be broadcast.
A13: Voicemail | B13: Off / On
A14: Voicemail / Greeting | B14: No audio selected or recorded / <Wav file name>
A15: Voicemail / Email Notification | B15: Off On (Send email notification to members for group voicemails)
A16: Members | B16: <User 1> | C16: Ext:
B17: <User 2> | C17: Ext:
B18: <User 3> | C18: Ext:
B19: <User 4> | C19: Ext:
B20: <User 5> | C20: Ext:
A21: Owners | B21: <User 1>
B22: <User 2>
B23: <User 3>
B24: <User 4>
B25: <User 5>

Sheet Groups for VM - Nebula
A1: Group Config | B1: About Groups - Genesys Cloud Resource Center (mypurecloud.com)
B2: About setting up Groups (admins) - Genesys Cloud Resource Center (mypurecloud.com)
A3: Group Name | B3: Type | C3: Visibility | D3: Include owners | E3: Enable Calls | F3: Group Phone Number / Extension | G3: Call Route Type | H3: Rotate Calls | I3: Stop Ringing | J3: Overflow | K3: Overflow / Back-up Contact | L3: Voicemail | M3: Voicemail / Greeting | N3: Voicemail / Email Notification | O3: Members | P3: Owners
A4: Broker_VM_Opt_Greater_Atlanta_DN_Group | B4: Official | C4: Public | D4: yes | E4: yes | F4: 8000 | G4: Rotary | H4: 12 | I4: 10 | J4: no | L4: yes | P4: Pooja Konda, Anirban Chakravarty, Simonti Sen,QA users
A5: Broker_VM_Opt_Greater_Chicago_DN_Group | B5: Official | C5: Public | D5: yes | E5: yes | F5: 8001 | G5: Rotary | H5: 12 | I5: 10 | J5: no | L5: yes | P5: Pooja Konda, Anirban Chakravarty, Simonti Sen,QA users
A6: Broker_VM_Opt_Pennsylvania_DN_Group | B6: Official | C6: Public | D6: yes | E6: yes | F6: 8002 | G6: Rotary | H6: 12 | I6: 10 | J6: no | L6: yes | P6: Pooja Konda, Anirban Chakravarty, Simonti Sen,QA users
A7: Team_Smith_Gusto_OF_Group | B7: Official | C7: Public | D7: yes | E7: yes | F7: 8003 | G7: Rotary | H7: 12 | I7: 10 | J7: no | L7: yes | P7: Pooja Konda, Anirban Chakravarty, Simonti Sen,QA users
A8: Broker_VM_Opt_Texas_DN_Group | B8: Official | C8: Public | D8: yes | E8: yes | F8: 8004 | G8: Rotary | H8: 12 | I8: 10 | J8: no | L8: yes | P8: Pooja Konda, Anirban Chakravarty, Simonti Sen,QA users
A9: Team_Jefferies_OF_Group | B9: Official | C9: Public | D9: yes | E9: yes | F9: 8005 | G9: Rotary | H9: 12 | I9: 10 | J9: no | L9: yes | P9: Pooja Konda, Anirban Chakravarty, Simonti Sen,QA users
A10: Broker_VM_Opt_No_Cal_DN_Group | B10: Official | C10: Public | D10: yes | E10: yes | F10: 8006 | G10: Rotary | H10: 12 | I10: 10 | J10: no | L10: yes | P10: Pooja Konda, Anirban Chakravarty, Simonti Sen,QA users
A11: Team_Smith_OF_Group | B11: Official | C11: Public | D11: yes | E11: yes | F11: 8007 | G11: Rotary | H11: 12 | I11: 10 | J11: no | L11: yes | P11: Pooja Konda, Anirban Chakravarty, Simonti Sen,QA users
A12: Broker_VM_Opt_Florida_DN_Group | B12: Official | C12: Public | D12: yes | E12: yes | F12: 8008 | G12: Rotary | H12: 12 | I12: 10 | J12: no | L12: yes | P12: Pooja Konda, Anirban Chakravarty, Simonti Sen,QA users
A13: Team_Kober_OF_Group | B13: Official | C13: Public | D13: yes | E13: yes | F13: 8009 | G13: Rotary | H13: 12 | I13: 10 | J13: no | L13: yes | P13: Pooja Konda, Anirban Chakravarty, Simonti Sen,QA users
A14: Broker_VM_Opt_Greater_New_York_DN_Group | B14: Official | C14: Public | D14: yes | E14: yes | F14: 8010 | G14: Rotary | H14: 12 | I14: 10 | J14: no | L14: yes | P14: Pooja Konda, Anirban Chakravarty, Simonti Sen,QA users
A15: Broker_VM_Opt_Great_Lakes_DN_Group | B15: Official | C15: Public | D15: yes | E15: yes | F15: 8011 | G15: Rotary | H15: 12 | I15: 10 | J15: no | L15: yes | P15: Pooja Konda, Anirban Chakravarty, Simonti Sen,QA users
... A202: Broker_VM_Opt_Broker_Sequoia_OF_Group | B202: Official | C202: Public | D202: yes | E202: yes | F202: 8198 | G202: Rotary | H202: 12 | I202: 10 | J202: no | L202: yes | P202: Pooja Konda, Anirban Chakravarty, Simonti Sen,QA users

Sheet Groups for VM - Supernova
A1: Group Config | B1: About Groups - Genesys Cloud Resource Center (mypurecloud.com)
B2: About setting up Groups (admins) - Genesys Cloud Resource Center (mypurecloud.com)
A3: Group Name | B3: Type | C3: Visibility | D3: Include owners | E3: Enable Calls | F3: Group Phone Number / Extension | G3: Call Route Type | H3: Rotate Calls | I3: Stop Ringing | J3: Overflow | K3: Overflow / Back-up Contact | L3: Voicemail | M3: Voicemail / Greeting | N3: Voicemail / Email Notification | O3: Members | P3: Owners
A4: Broker_VM_Opt_Greater_Atlanta_DN_Group | B4: Official | C4: Public | D4: yes | E4: yes | F4: 8000 | G4: Rotary | H4: 12 | I4: 10 | J4: no | L4: yes | O4: caroline_ferguson@glic.com,Erin_Ziegert@glic.com,rachel_gustave@glic.com,whitnee_steger@glic.com,amber_brittian@glic.com,seindhy_piquion@glic.com | P4: Pooja Konda, Anirban Chakravarty, Simonti Sen, Garrett Napier, Dan Wolf, Robert J. Paxton
A5: Broker_VM_Opt_Greater_Chicago_DN_Group | B5: Official | C5: Public | D5: yes | E5: yes | F5: 8001 | G5: Rotary | H5: 12 | I5: 10 | J5: no | L5: yes | O5: darian_briemann@glic.com,rachael_evers@glic.com,agatha_gallion@glic.com | P5: Pooja Konda, Anirban Chakravarty, Simonti Sen, Garrett Napier, Dan Wolf, Robert J. Paxton
A6: Broker_VM_Opt_Pennsylvania_DN_Group | B6: Official | C6: Public | D6: yes | E6: yes | F6: 8002 | G6: Rotary | H6: 12 | I6: 10 | J6: no | L6: yes | O6: teri_klarner@glic.com,Dana_VanNatten@glic.com,lamika_mcnichols@glic.com,Susan_Morrow@glic.com | P6: Pooja Konda, Anirban Chakravarty, Simonti Sen, Garrett Napier, Dan Wolf, Robert J. Paxton
A7: Team_Smith_Gusto_OF_Group | B7: Official | C7: Public | D7: yes | E7: yes | F7: 8003 | G7: Rotary | H7: 12 | I7: 10 | J7: no | L7: yes | O7: josey_wendler@glic.com,karen_hietpas@glic.com,amy_nyce@glic.com,catherine_malitsis@glic.com,angela_louros@glic.com,Jennifer_VanHandel@glic.com | P7: Pooja Konda, Anirban Chakravarty, Simonti Sen, Garrett Napier, Dan Wolf, Robert J. Paxton
A8: Broker_VM_Opt_Texas_DN_Group | B8: Official | C8: Public | D8: yes | E8: yes | F8: 8004 | G8: Rotary | H8: 12 | I8: 10 | J8: no | L8: yes | O8: teri_wussow@glic.com,cassidy_beahn@glic.com,quinnetta_crayton@glic.com,patricia_rollberg@glic.com,christine_eder@glic.com,Nicholas_Rossi-Marino@glic.com,Amanda_Matczak@glic.com | P8: Pooja Konda, Anirban Chakravarty, Simonti Sen, Garrett Napier, Dan Wolf, Robert J. Paxton
A9: Team_Jefferies_OF_Group | B9: Official | C9: Public | D9: yes | E9: yes | F9: 8005 | G9: Rotary | H9: 12 | I9: 10 | J9: no | L9: yes | O9: Amy_Hietpas@glic.com,asha_cull@glic.com,ashley_natali@glic.com,bethann_bogucki@glic.com,Brian_Rusch@glic.com,Mary-Jane_Lower@glic.com,Shelley_Zeegers@glic.com,Stephanie_werley@glic.com,elizabeth_wapinski@glic.com,kathy_wilson@glic.com,Alyssa_Reed@glic.com,amber_richardson@glic.com,crystal_mathews@glic.com,Deborah_A_Berger@glic.com,Milagros_Jordan@glic.com,taylor_x_johnson@glic.com | P9: Pooja Konda, Anirban Chakravarty, Simonti Sen, Garrett Napier, Dan Wolf, Robert J. Paxton
A10: Broker_VM_Opt_No_Cal_DN_Group | B10: Official | C10: Public | D10: yes | E10: yes | F10: 8006 | G10: Rotary | H10: 12 | I10: 10 | J10: no | L10: yes | O10: chris_bucklin@glic.com,crystal_sjoquist@glic.com,tempestt_dubose@glic.com,Cari_Taylor@glic.com,Candice_Guehrn@glic.com,amber_rice@glic.com | P10: Pooja Konda, Anirban Chakravarty, Simonti Sen, Garrett Napier, Dan Wolf, Robert J. Paxton
A11: Team_Smith_OF_Group | B11: Official | C11: Public | D11: yes | E11: yes | F11: 8007 | G11: Rotary | H11: 12 | I11: 10 | J11: no | L11: yes | O11: Jeff_Stadler@glic.com,RCook@glic.com,shannon_bartlett@glic.com | P11: Pooja Konda, Anirban Chakravarty, Simonti Sen, Garrett Napier, Dan Wolf, Robert J. Paxton
A12: Broker_VM_Opt_Florida_DN_Group | B12: Official | C12: Public | D12: yes | E12: yes | F12: 8008 | G12: Rotary | H12: 12 | I12: 10 | J12: no | L12: yes | O12: Brittany_Collier@glic.com,Cynthia_Mateer@glic.com,Lisa_Manescu@glic.com,Wendy_Schoenberger@glic.com,megan_schalund@glic.com,brianna_crager@glic.com | P12: Pooja Konda, Anirban Chakravarty, Simonti Sen, Garrett Napier, Dan Wolf, Robert J. Paxton
A13: Team_Kober_OF_Group | B13: Official | C13: Public | D13: yes | E13: yes | F13: 8009 | G13: Rotary | H13: 12 | I13: 10 | J13: no | L13: yes | O13: amy_nyce@glic.com,angela_louros@glic.com,Beth_Ritchie@glic.com,bryan_mccray@glic.com,catherine_malitsis@glic.com,Charmaine_Espinoza@glic.com,Deb_Doyne@glic.com,Jennifer_VanHandel@glic.com,josey_wendler@glic.com,karen_hietpas@glic.com,Kayla_Murtaugh@glic.com,latoya_moore@glic.com,Lina_Alvarez@glic.com,Mandy_Otto@glic.com,michael_santos@glic.com,Michelle_Radtke@glic.com,natalie_indelicato@glic.com,ryan_p_thomas@glic.com,Sue_Reppert@glic.com | P13: Pooja Konda, Anirban Chakravarty, Simonti Sen, Garrett Napier, Dan Wolf, Robert J. Paxton
A14: Broker_VM_Opt_Greater_New_York_DN_Group | B14: Official | C14: Public | D14: yes | E14: yes | F14: 8010 | G14: Rotary | H14: 12 | I14: 10 | J14: no | L14: yes | O14: tammy_billheimer@glic.com,zach_kickbusch@glic.com,Ashlee_Mereness@glic.com,Cindy_Kriewaldt@glic.com,Michelle_Radtke@glic.com,Patricia_Young@glic.com,pamela_barrett@glic.com,Sandy_Vandermoss@glic.com,cindy_johnson@glic.com | P14: Pooja Konda, Anirban Chakravarty, Simonti Sen, Garrett Napier, Dan Wolf, Robert J. Paxton
A15: Broker_VM_Opt_Great_Lakes_DN_Group | B15: Official | C15: Public | D15: yes | E15: yes | F15: 8011 | G15: Rotary | H15: 12 | I15: 10 | J15: no | L15: yes | O15: Sara_Leitermann@glic.com,mitchell_roepcke@glic.com,Jessica_Knutson@glic.com,Barb_Hanson@glic.com,Natasha_Yancey@glic.com,sydney_hassler@glic.com,jennifer_lison@glic.com,laterrica_harris@glic.com | P15: Pooja Konda, Anirban Chakravarty, Simonti Sen, Garrett Napier, Dan Wolf, Robert J. Paxton
... A23: Broker_VM_Opt_Pacific_SW_DN_Group | B23: Official | C23: Public | D23: yes | E23: yes | F23: 8019 | G23: Rotary | H23: 12 | I23: 10 | J23: no | L23: yes | O23: Rebecca_Buchinger@glic.com,Vonnie_Riehle@glic.com,christa_powell@glic.com,katie_romo@glic.com,leigh_schneider@glic.com,hazel_delareto@glic.com,theresa_ludtke@glic.com | P23: Pooja Konda, Anirban Chakravarty, Simonti Sen, Garrett Napier, Dan Wolf, Robert J. Paxton
A24: Dental_Closed_Group | B24: Official | C24: Public | D24: yes | E24: yes | F24: 8020 | G24: Rotary | H24: 12 | I24: 10 | J24: no | L24: yes | P24: Pooja Konda, Anirban Chakravarty, Simonti Sen, Garrett Napier, Dan Wolf, Robert J. Paxton
A25: EDI_VM | B25: Official | C25: Public | D25: yes | E25: yes | F25: 8021 | G25: Rotary | H25: 12 | I25: 10 | J25: no | L25: yes | O25: AISVARIYA_R@glic.com,aman_hooda@glic.com,Ankit_Sher_Singh@glic.com,arjun_ekambaram@glic.com,bhuvaneswari_kaliyaperumal@glic.com,Cheshta_Singh@glic.com,christine_strickler@glic.com,david_r_kennedy@glic.com,deepak_pathak@glic.com,Gagan_Nawani@glic.com,Heather_Carpenter@glic.com,jamuna_x_kailasam@glic.com,jana_peterson@glic.com,Jeremy_Zeegers@glic.com,jonathan_gracer@glic.com,Kate_Hennessey@glic.com,kristen_aiello@glic.com,kristin_soldridge@glic.com,Kristine_Muench@glic.com,kumaresan_subramanian@glic.com,Lena_P_Xiong@glic.com,Lisa_A_Reier@glic.com,Mary_Zoromski@glic.com,matt_guidry@glic.com,maurice_tucker@glic.com,michael_ulmen@glic.com,mohit_dixit@glic.com,Nandakumar_Ganesan@glic.com,nicholas_kline@glic.com,nitesh_n@glic.com,noor-mohammed_methapillai-marasikayer@glic.com,pamela_stanek@glic.com,pratyush_jha@glic.com,Priya_Natarajan@glic.com,Rekha_Pandey@glic.com,senthamilmanimaran_karunanithi@glic.com,shafara_bridges@glic.com,shristi_singh@glic.com,simson_chellathurai@glic.com | P25: Pooja Konda, Anirban Chakravarty, Simonti Sen, Garrett Napier, Dan Wolf, Robert J. Paxton
A26: HW_Deduction_VM_Group | B26: Official | C26: Public | D26: yes | E26: yes | F26: 8022 | G26: Rotary | H26: 12 | I26: 10 | J26: no | L26: yes | P26: Pooja Konda, Anirban Chakravarty, Simonti Sen, Garrett Napier, Dan Wolf, Robert J. Paxton
A27: National_Conversion_Closed_Group | B27: Official | C27: Public | D27: yes | E27: yes | F27: 8023 | G27: Rotary | H27: 12 | I27: 10 | J27: no | L27: yes | O27: brandy_dunlow@glic.com,Cindy_Delfosse@glic.com,Denise_Eckert@glic.com,Leah_Williamson@glic.com,pamela_olson@glic.com,rebecca_jansen@glic.com,regina_nelson@glic.com,robin_dobberstein@glic.com | P27: Pooja Konda, Anirban Chakravarty, Simonti Sen, Garrett Napier, Dan Wolf, Robert J. Paxton
A28: National_Conversion_Exception_Group | B28: Official | C28: Public | D28: yes | E28: yes | F28: 8024 | G28: Rotary | H28: 12 | I28: 10 | J28: no | L28: yes | O28: brandy_dunlow@glic.com,Cindy_Delfosse@glic.com,Denise_Eckert@glic.com,Leah_Williamson@glic.com,pamela_olson@glic.com,rebecca_jansen@glic.com,regina_nelson@glic.com,robin_dobberstein@glic.com | P28: Pooja Konda, Anirban Chakravarty, Simonti Sen, Garrett Napier, Dan Wolf, Robert J. Paxton
A29: National_Conversion_Holiday_Group | B29: Official | C29: Public | D29: yes | E29: yes | F29: 8025 | G29: Rotary | H29: 12 | I29: 10 | J29: no | L29: yes | O29: brandy_dunlow@glic.com,Cindy_Delfosse@glic.com,Denise_Eckert@glic.com,Leah_Williamson@glic.com,pamela_olson@glic.com,rebecca_jansen@glic.com,regina_nelson@glic.com,robin_dobberstein@glic.com | P29: Pooja Konda, Anirban Chakravarty, Simonti Sen, Garrett Napier, Dan Wolf, Robert J. Paxton
A30: National_Conversion_Unstaffed_Group | B30: Official | C30: Public | D30: yes | E30: yes | F30: 8026 | G30: Rotary | H30: 12 | I30: 10 | J30: no | L30: yes | O30: brandy_dunlow@glic.com,Cindy_Delfosse@glic.com,Denise_Eckert@glic.com,Leah_Williamson@glic.com,pamela_olson@glic.com,rebecca_jansen@glic.com,regina_nelson@glic.com,robin_dobberstein@glic.com | P30: Pooja Konda, Anirban Chakravarty, Simonti Sen, Garrett Napier, Dan Wolf, Robert J. Paxton
A31: Premier_Planholder_Group | B31: Official | C31: Public | D31: yes | E31: yes | F31: 8027 | G31: Rotary | H31: 12 | I31: 10 | J31: no | L31: yes | O31: alicia_kettner@glic.com,amy_Erickson@glic.com,amy_vaupel@glic.com,Anna_Lee@glic.com,brandon_velez@glic.com,cynara_mayer@glic.com,Destiny_Harris@glic.com,Jennifer_Schoenick@glic.com,Karen_Miletto@glic.com,lindsay_shiner@glic.com,Mary_Krueger@glic.com,Melanie_Stellmach@glic.com,rachel_a_showman@glic.com,Randi_Trudeau@glic.com,selena_rippy@glic.com,Sue_Steffens@glic.com,trent_wright@glic.com | P31: Pooja Konda, Anirban Chakravarty, Simonti Sen, Garrett Napier, Dan Wolf, Robert J. Paxton
A32: IPSIEX_Closed_CA_Group | B32: Official | C32: Public | D32: yes | E32: yes | F32: 8028 | G32: Rotary | H32: 12 | I32: 10 | J32: no | L32: yes | P32: Pooja Konda, Anirban Chakravarty, Simonti Sen, Garrett Napier, Dan Wolf, Robert J. Paxton
A33: IL_LifeClaims_Unstaffed_Group | B33: Official | C33: Public | D33: yes | E33: yes | F33: 8029 | G33: Rotary | H33: 12 | I33: 10 | J33: no | L33: yes | P33: Pooja Konda, Anirban Chakravarty, Simonti Sen, Garrett Napier, Dan Wolf, Robert J. Paxton
A34: DI_DTC_Agency_Assist_Group | B34: Official | C34: Public | D34: yes | E34: yes | F34: 8030 | G34: Rotary | H34: 12 | I34: 10 | J34: no | L34: yes | P34: Pooja Konda, Anirban Chakravarty, Simonti Sen, Garrett Napier, Dan Wolf, Robert J. Paxton
A35: IM_Agent_Closed_Group | B35: Official | C35: Public | D35: yes | E35: yes | F35: 8031 | G35: Rotary | H35: 12 | I35: 10 | J35: no | L35: yes | P35: Pooja Konda, Anirban Chakravarty, Simonti Sen, Garrett Napier, Dan Wolf, Robert J. Paxton
A36: IM_Agent_Unstaffed_Group | B36: Official | C36: Public | D36: yes | E36: yes | F36: 8032 | G36: Rotary | H36: 12 | I36: 10 | J36: no | L36: yes | O36: luz_alvarado@glic.com | P36: Pooja Konda, Anirban Chakravarty, Simonti Sen, Garrett Napier, Dan Wolf, Robert J. Paxton
A37: CLM_Unstaffed_Group | B37: Official | C37: Public | D37: yes | E37: yes | F37: 8033 | G37: Rotary | H37: 12 | I37: 10 | J37: no | L37: yes | P37: Pooja Konda, Anirban Chakravarty, Simonti Sen, Garrett Napier, Dan Wolf, Robert J. Paxton
A38: IL_Elite_Group | B38: Official | C38: Public | D38: yes | E38: yes | F38: 8034 | G38: Rotary | H38: 12 | I38: 10 | J38: no | L38: yes | O38: Evangelista_Mora@glic.com,harrison_scheffler@glic.com,Krista_Demyan@glic.com,martin_goldstein@glic.com,samantha_kenyon@glic.com,warren_kwan@glic.com | P38: Pooja Konda, Anirban Chakravarty, Simonti Sen, Garrett Napier, Dan Wolf, Robert J. Paxton
A39: IL_LifeClaims_Closed_Group | B39: Official | C39: Public | D39: yes | E39: yes | F39: 8035 | G39: Rotary | H39: 12 | I39: 10 | J39: no | L39: yes | P39: Pooja Konda, Anirban Chakravarty, Simonti Sen, Garrett Napier, Dan Wolf, Robert J. Paxton
A40: IL_LifeClaims_Exception_Group | B40: Official | C40: Public | D40: yes | E40: yes | F40: 8036 | G40: Rotary | H40: 12 | I40: 10 | J40: no | L40: yes | P40: Pooja Konda, Anirban Chakravarty, Simonti Sen, Garrett Napier, Dan Wolf, Robert J. Paxton
A41: IL_LifeClaims_Holiday_Group | B41: Official | C41: Public | D41: yes | E41: yes | F41: 8037 | G41: Rotary | H41: 12 | I41: 10 | J41: no | L41: yes | P41: Pooja Konda, Anirban Chakravarty, Simonti Sen, Garrett Napier, Dan Wolf, Robert J. Paxton
A42: eApp_Unstaffed_Group | B42: Official | C42: Public | D42: yes | E42: yes | F42: 8038 | G42: Rotary | H42: 12 | I42: 10 | J42: no | L42: yes | P42: Pooja Konda, Anirban Chakravarty, Simonti Sen, Garrett Napier, Dan Wolf, Robert J. Paxton
A43: RSTPA_Closed_Group | B43: Official | C43: Public | D43: yes | E43: yes | F43: 8039 | G43: Rotary | H43: 12 | I43: 10 | J43: no | L43: yes | P43: Pooja Konda, Anirban Chakravarty, Simonti Sen, Garrett Napier, Dan Wolf, Robert J. Paxton
A44: GSA_Trading_Group | B44: Official | C44: Public | D44: yes | E44: yes | F44: 8040 | G44: Rotary | H44: 12 | I44: 10 | J44: no | L44: yes | P44: Pooja Konda, Anirban Chakravarty, Simonti Sen, Garrett Napier, Dan Wolf, Robert J. Paxton
A45: GSA_Client_Group | B45: Official | C45: Public | D45: yes | E45: yes | F45: 8041 | G45: Rotary | H45: 12 | I45: 10 | J45: no | L45: yes | P45: Pooja Konda, Anirban Chakravarty, Simonti Sen, Garrett Napier, Dan Wolf, Robert J. Paxton
A46: GSA_Advisor_Group | B46: Official | C46: Public | D46: yes | E46: yes | F46: 8042 | G46: Rotary | H46: 12 | I46: 10 | J46: no | L46: yes | P46: Pooja Konda, Anirban Chakravarty, Simonti Sen, Garrett Napier, Dan Wolf, Robert J. Paxton
A47: Tricia_VM_Group | B47: Official | C47: Public | D47: yes | E47: yes | F47: 8043 | G47: Rotary | H47: 12 | I47: 10 | J47: no | L47: yes | O47: brenna_kern@glic.com,Haripriya_Nagarajan@glic.com,karthikeyan_jaganathan@glic.com,Marlene_J_Dupuis@glic.com,Patrick_R_Harlan@glic.com,pavankumar_kothapalli@glic.com,simonti_test@glic.com | P47: Pooja Konda, Anirban Chakravarty, Simonti Sen, Garrett Napier, Dan Wolf, Robert J. Paxton
...

Sheet Groups - Skill Expressions
A1: Skill Expression | Q1: About groups - Genesys Cloud Resource Center (mypurecloud.com)
A2: Skills Expression Groups_values only.xlsx | B2: see spreadsheet for details

Sheet External Contacts
A1: External Contacts | D1: About External Contacts - Genesys Cloud Resource Center (mypurecloud.com)
A2: Contact ID | B2: Contact First Name | C2: Contact Last Name | D2: Phone Number | E2: Built Prod | F2: Built Dev
A3: 12125988000 | B3: CRP_Operators | C3: IVR | D3: +12125988000 | E3: Yes | F3: Yes
A4: 12125988016 | B4: MDRT / Joe Cox | C4: External | D4: +12125988016 | E4: Yes | F4: Yes
A5: 12125988327 | B5: S2P Help Desk | C5: External | D5: +12125988327 | E5: Yes | F5: Yes
A6: 12125988386 | B6: Proxy Voting - Rose Romano | C6: External | D6: +12125988386 | E6: Yes | F6: Yes
A7: 12129192148 | B7: Mail Room - Hudson Yards | C7: External | D7: +12129192148 | E7: Yes | F7: Yes
A8: 12129192150 | B8: Reg. 60 / Jevon Aarons - Fax 212-919-4016 | C8: External | D8: +12129192150 | E8: Yes | F8: Yes
A9: 12129192386 | B9: Annuity Sales Desk / Business Development | C9: External | D9: +12129192386 | E9: Yes | F9: Yes
A10: 12129192699 | B10: Cafe - Hudson Yards | C10: External | D10: +12129192699 | E10: Yes | F10: Yes
A11: 12129192986 | B11: Security - Hudson Yards | C11: External | D11: +12129192986 | E11: Yes | F11: Yes
A12: 12129193036 | B12: Subrogation & Bankruptcy / Arleta Strus | C12: External | D12: +12129193036 | E12: Yes | F12: Yes
A13: 12129194558 | B13: Lost and Found - Hudson Yards | C13: External | D13: +12129194558 | E13: Yes | F13: Yes
A14: 12129195021 | B14: Security - Holmdel | C14: External | D14: +12129195021 | E14: Yes | F14: Yes
... A25: 14133954100 | B25: Berkshire Office | C25: External | D25: +14133954100 | E25: Yes | F25: Yes
A26: 14133954100B | B26: Security - Pittsfield / Berkshire | C26: External | D26: +14133954100 | E26: Yes | F26: Yes
A27: 14133954305 | B27: Cafe - Pittsfield | C27: External | D27: +14133954305 | E27: Yes | F27: Yes
A28: 14133954644 | B28: Mail Room - Berkshire/ Pittsfield - Kathleen Loria | C28: External | D28: +14133954644 | E28: Yes | F28: Yes
A29: 14133954791 | B29: Subpoenas / Subrogation - Amanda Carpenter - send subpoenas Certified to HO Attn Law Dept | C29: External | D29: +14133954791 | E29: Yes | F29: Yes
A30: 15083088396 | B30: Jim Magner / BRC | C30: External | D30: +15083088396 | E30: Yes | F30: Yes
A31: 15094686000 | B31: CRP_WROMainMenu | C31: IVR | D31: +15094686000 | E31: Yes | F31: Yes
A32: 15094686724 | B32: Cafe - Spokane | C32: External | D32: +15094686724 | E32: Yes | F32: Yes
A33: 15551001524 | B33: IPS_DTC | C33: IVR | D33: +15551001524 | E33: Yes | F33: Yes
A34: 15552220094 | B34: IM_PDA | C34: IVR | D34: +15552220094 | E34: Yes | F34: Yes
A35: 15555554008 | B35: GRP_STD | C35: IVR | D35: +15555554008 | E35: Yes | F35: Yes
A36: 15555554096 | B36: IPS_IEX | C36: IVR | D36: +15555554096 | E36: Yes | F36: Yes
A37: 15555559005 | B37: CRP_HR | C37: IVR | D37: +15555559005 | E37: Yes | F37: Yes
A38: 15555559033 | B38: GRP_TPAMenu | C38: IVR | D38: +15555559033 | E38: Yes | F38: Yes
... A326: 18002682525 | B326: State Disability / Paid Family Leave / STD | C326: External | D326: +18002682525 | E326: Yes | F326: Yes
A327: 18002682525B | B327: Group - STD Claims | C327: External | D327: +18002682525 | E327: Yes | F327: Yes
A328: 18002733330 | B328: GRP_MDC | C328: IVR | D328: +18002733330 | E328: Yes | F328: Yes
A329: 18002891337 | B329: Sykes Payment | C329: External | D329: +18002891337 | E329: Yes | F329: Yes
A330: 18002998654 | B330: Guardian Corporate Help Desk | C330: IVR | D330: +18002998654 | E330: Yes | F330: Yes
A331: 18003164015 | B331: ASL | C331: IVR | D331: +18003164015 | E331: Yes | F331: Yes
A332: 18003477443 | B332: Reed Group | C332: External | D332: +18003477443 | E332: Yes | F332: Yes
A333: 18003507314 | B333: IM_ICD | C333: IVR | D333: +18003507314 | E333: Yes | F333: Yes
A334: 18003565808 | B334: SGS / Small Group Sales Bethlehem | C334: External | D334: +18003565808 | E334: Yes | F334: Yes
A335: 18003867055 | B335: EAP - Member - Employee Assistance Program - M-F 9 to 8 Eastern | C335: External | D335: +18003867055 | E335: Yes | F335: Yes
A336: 18004335982 | B336: Group National Conversion Toll Free - Opt. 1 ext. 5696 - for Group policies that have been converted. | C336: External | D336: +18004335982 | E336: Yes | F336: Yes
A337: 18004335982B | B337: GRP_MRO_GCA | C337: IVR | D337: +18004335982 | E337: Yes | F337: Yes
...

Sheet Queues
A1: Built Prod | B1: Built Dev | C1: Queue Name | D1: Description | E1: Division | F1: Peer ID | G1: Outbound CID | H1: Outbound CID Name | I1: ACW Method | J1: ACW Timeout | K1: Scoring Method | L1: Routing Method | M1: Queue Evaluation Method | N1: BR1 EX | O1: BR1 TO | P1: BR1 Skills | Q1: BR1 SG | R1: BR1 MG | S1: Column6 | T1: Voice Alerting Timeout | U1: Voice Whisper Audio | V1: Voice SLA % (ex. 80) | W1: Voice SLA Target (20 seconds) | X1: Voice In Queue Flow | Y1: Script | Z1: Chat Alerting Timeout (30) | AA1: Chat Service Sevel % | AB1: Chat Service Level Target (20) | AC1: Chat Default Script | AD1: SMS Service Level % (80) | AE1: SMS Service Level Target (20) | AF1: Alerting Timeout (30) | AG1: SMS Default Script | AH1: SMS In-Queue Flow | AI1: Outbound SMS Number | AJ1: Email Service Level % | AK1: Email Service Level Target (86400) | AL1: Email Alerting Timeout (300) | AM1: Email Auto Answer | AN1: Outbound Email Address | AO1: In-queue Email Flow | AP1: Email Default Script | AQ1: Callback Service Level % (80) | AR1: Callback Service Level Target (20) | AS1: Callback Alerting Timeout (30) | AT1: Allow Agents to take ownership | AU1: Own Schedule Callback Time | AV1: Schedule Callback in Advance for | AW1: Voice Transcription | AX1: Manual Assignment | AY1: Advanced Routing | AZ1: Auto-Answer for all Digital Channels | BA1: Notes
C2: General_English | G2: 800 555-1234 | H2: Company Name | I2: Optional | K2: Conversation Score | M2: Disregard skills-next agent | N2: TIMEOUT_SECONDS | O2: 5 | P2: test 1 | Q2: test 1 = 1:Home | R2: bigTest1:none,bigTest2:none | T2: 8 | AX2: off | AZ2: off
G5: Information housed in separate spreadsheet - Mike W
C232: About contact center - Genesys Cloud Resource Center (mypurecloud.com)

Sheet BullseyeQueues
A1: Queue Name | B1: Description | C1: Division | D1: Peer ID | E1: Outbound CID | F1: Outbound CID Name | G1: ACW Method | H1: ACW Timeout | I1: Scoring Method | J1: Routing Method | K1: Queue Evaluation Method | L1: 1 BR EX | M1: 1 BR TO | N1: 1 BR Skills | O1: 1 BR SG | P1: 1 BR MG | Q1: 2 BR EX | R1: 2 BR TO | S1: 2 BR Skills | T1: 2 BR SG | U1: 2 BR MG | V1: 3 BR EX | W1: 3 BR TO | X1: 3 BR Skills | Y1: 3 BR SG | Z1: 3 BR MG | AA1: 4 BR EX | AB1: 4 BR TO | AC1: 4 BR Skills | AD1: 4 BR SG | AE1: 4 BR MG | AF1: 5 BR EX | AG1: 5 BR TO | AH1: 5 BR Skills | AI1: 5 BR SG | AJ1: 5 BR MG | AK1: 6 BR EX | AL1: 6 BR TO | AM1: 6 BR Skills | AN1: 6 BR SG | AO1: 6 BR MG | AP1: Voice Alerting Timeout | AQ1: Voice Whisper Audio | AR1: Voice SLA % (ex. 80) | AS1: Voice SLA Target (20 seconds) | AT1: Voice In Queue Flow | AU1: Script | AV1: Chat Alerting Timeout (30) | AW1: Chat Service Sevel % | AX1: Chat Service Level Target (20) | AY1: Chat Default Script | AZ1: SMS Service Level % (80) | BA1: SMS Service Level Target (20) | BB1: Alerting Timeout (30) | BC1: SMS Default Script | BD1: SMS In-Queue Flow | BE1: Outbound SMS Number | BF1: Email Service Level % | BG1: Email Service Level Target (86400) | BH1: Email Alerting Timeout (300) | BI1: Email Auto Answer | BJ1: Outbound Email Address | BK1: In-queue Email Flow | BL1: Email Default Script | BM1: Callback Service Level % (80) | BN1: Callback Service Level Target (20) | BO1: Callback Alerting Timeout (30) | BP1: Allow Agents to take ownership | BQ1: Own Schedule Callback Time | BR1: Schedule Callback in Advance for | BS1: Voice Transcription | BT1: Manual Assignment | BU1: Advanced Routing | BV1: Auto-Answer for all Digital Channels
A2: h4 | B2: ImportedQueue | C2: Home | E2: 8005551234 | F2: Company Name | G2: MANDATORY | I2: Conversation Score | K2: BEST | L2: TIMEOUT_SECONDS | M2: 5 | N2: test 1 | O2: test 1 = 1:Home | P2: bigTest1:none,bigTest2:none | Q2: TIMEOUT_SECONDS | R2: 5 | S2: test 2|test 3 | T2: test 1 = 2:Home | U2: bigTest3:none,bigTest4:none | V2: TIMEOUT_SECONDS | W2: 5 | X2: test 4 | Y2: test 1 = 3:Home | Z2: bigTest5:none,bigTest6:none | AP2: 8 | AR2: 80 | AS2: 20 | BT2: off | BV2: off
A3: h5 | B3: ImportedQueue | C3: Home | E3: 8005551234 | F3: Company Name | G3: OPTIONAL | I3: Conversation Score | K3: BEST | L3: TIMEOUT_SECONDS | M3: 5 | N3: test 1 | O3: test 1 = 1:Home | P3: bigTest1:none,bigTest2:none | Q3: TIMEOUT_SECONDS | R3: 5 | S3: test 2|test 3 | T3: test 1 = 2:Home | U3: bigTest3:none,bigTest4:none | V3: TIMEOUT_SECONDS | W3: 5 | X3: test 4 | Y3: test 1 = 3:Home | Z3: bigTest5:none,bigTest6:none | AP3: 8 | AR3: 80 | AS3: 20
A4: h6 | B4: ImportedQueue | C4: Home | E4: 8005551234 | F4: Company Name | G4: MANDATORY_TIMEOUT | H4: 5 | I4: Conversation Score | K4: ALL | L4: TIMEOUT_SECONDS | M4: 5 | N4: test 1 | O4: test 1 = 1:Home | P4: bigTest1:none,bigTest2:none | Q4: TIMEOUT_SECONDS | R4: 5 | S4: test 2|test 3 | T4: test 1 = 2:Home | U4: bigTest3:none,bigTest4:none | V4: TIMEOUT_SECONDS | W4: 5 | X4: test 4 | Y4: test 1 = 3:Home | Z4: bigTest5:none,bigTest6:none | AP4: 8 | AR4: 80 | AS4: 20

Sheet BullseyeQueuesCSV
A1: queue | B1: division | C1: acw | D1: inQueueFlow | E1: routingRules | F1: callScript | G1: groupRouting | H1: bullseye | I1: MemberGroups | J1: evaluation | K1: callerIDNum | L1: callerIDName | M1: alerting_timeout_seconds | N1: slPercentage | O1: slDuration_ms
A2: =BullseyeQueues!A2 -> h4 | B2: =BullseyeQueues!C2 -> Home | C2: =_xlfn.CONCAT(BullseyeQueues!G2,IF(OR(BullseyeQueues!G2="MANDATORY",BullseyeQueues!G2="OPTIONAL"),"",_xlfn.CONCAT(":",BullseyeQueues!H2))) -> MANDATORY | D2: =IF(ISBLANK(BullseyeQueues!AT2),"Default In-Queue Flow",BullseyeQueues!AT2) -> Default In-Queue Flow | F2: =IF(ISBLANK(BullseyeQueues!AU2),"",BullseyeQueues!AU2) | H2: =IF(ISBLANK(BullseyeQueues!L2),"",_xlfn.CONCAT(BullseyeQueues!L2,":",BullseyeQueues!M2,":",BullseyeQueues!N2,IF(ISBLANK(BullseyeQueues!Q2),"",_xlfn.CONCAT(",",BullseyeQueues!Q2,":",BullseyeQueues!R2,":",BullseyeQueues!S2,IF(ISBLANK(BullseyeQueues!V2),"",_xlfn.CONCAT(",",BullseyeQueues!V2,":",BullseyeQueues!W2,":",BullseyeQueues!X2,IF(ISBLANK(BullseyeQueues!AA2),"",_xlfn.CONCAT(",",BullseyeQueues!AA2,":",BullseyeQueues!AB2,":",BullseyeQueues!AC2,IF(ISBLANK(BullseyeQueues!AF2),"",_xlfn.CONCAT(",",BullseyeQueues!AF2,":",BullseyeQueues!AG2,":",BullseyeQueues!AH2,IF(ISBLANK(BullseyeQueues!AK2),"",_xlfn.CONCAT(",",BullseyeQueues!AK2,":",BullseyeQueues!AL2,":",BullseyeQueues!AM2)))))))))))) -> TIMEOUT_SECONDS:5:test 1,TIMEOUT_SECONDS:5:test 2|test 3,TIMEOUT_SECONDS:5:test 4 | I2: =_xlfn.CONCAT(IF(ISBLANK(BullseyeQueues!$O2),"",BullseyeQueues!$O2),IF(ISBLANK(BullseyeQueues!$P2),"",IF(ISBLANK(BullseyeQueues!$O2),BullseyeQueues!$P2,_xlfn.CONCAT(",",BullseyeQueues!$P2))),"|",IF(ISBLANK(BullseyeQueues!T2),"",BullseyeQueues!T2),IF(ISBLANK(BullseyeQueues!U2),"",IF(ISBLANK(BullseyeQueues!T2),BullseyeQueues!U2,_xlfn.CONCAT(",",BullseyeQueues!U2))),"|",IF(ISBLANK(BullseyeQueues!Y2),"",BullseyeQueues!Y2),IF(ISBLANK(BullseyeQueues!Z2),"",IF(ISBLANK(BullseyeQueues!Y2),BullseyeQueues!Z2,_xlfn.CONCAT(",",BullseyeQueues!Z2))),"|",IF(ISBLANK(BullseyeQueues!AD2),"",BullseyeQueues!AD2),IF(ISBLANK(BullseyeQueues!AE2),"",IF(ISBLANK(BullseyeQueues!AD2),BullseyeQueues!AE2,_xlfn.CONCAT(",",BullseyeQueues!AE2))),"|",IF(ISBLANK(BullseyeQueues!AI2),"",BullseyeQueues!AI2),IF(ISBLANK(BullseyeQueues!AJ2),"",IF(ISBLANK(BullseyeQueues!AI2),BullseyeQueues!AJ2,_xlfn.CONCAT(",",BullseyeQueues!AJ2))),"|",IF(ISBLANK(BullseyeQueues!AN2),"",BullseyeQueues!AN2),IF(ISBLANK(BullseyeQueues!AO2),"",IF(ISBLANK(BullseyeQueues!AN2),BullseyeQueues!AO2,_xlfn.CONCAT(",",BullseyeQueues!AO2)))) -> test 1 = 1:Home,bigTest1:none,bigTest2:none|test 1 = 2:Home,bigTest3:none,bigTest4:none|test 1 = 3:Home,bigTest5:none,bigTest6:none||| | J2: =BullseyeQueues!K2 -> BEST | K2: =BullseyeQueues!E2 -> 8005551234 | L2: =BullseyeQueues!F2 -> Company Name | M2: =BullseyeQueues!AP2 -> 8 | N2: =BullseyeQueues!AR2/100 -> 0.8 | O2: =BullseyeQueues!AS2*1000 -> 20000
A3: =BullseyeQueues!A3 -> h5 | B3: =BullseyeQueues!C3 -> Home | C3: =_xlfn.CONCAT(BullseyeQueues!G3,IF(OR(BullseyeQueues!G3="MANDATORY",BullseyeQueues!G3="OPTIONAL"),"",_xlfn.CONCAT(":",BullseyeQueues!H3))) -> OPTIONAL | D3: =IF(ISBLANK(BullseyeQueues!AT3),"Default In-Queue Flow",BullseyeQueues!AT3) -> Default In-Queue Flow | F3: =IF(ISBLANK(BullseyeQueues!AU3),"",BullseyeQueues!AU3) | H3: =IF(ISBLANK(BullseyeQueues!L3),"",_xlfn.CONCAT(BullseyeQueues!L3,":",BullseyeQueues!M3,":",BullseyeQueues!N3,IF(ISBLANK(BullseyeQueues!Q3),"",_xlfn.CONCAT(",",BullseyeQueues!Q3,":",BullseyeQueues!R3,":",BullseyeQueues!S3,IF(ISBLANK(BullseyeQueues!V3),"",_xlfn.CONCAT(",",BullseyeQueues!V3,":",BullseyeQueues!W3,":",BullseyeQueues!X3,IF(ISBLANK(BullseyeQueues!AA3),"",_xlfn.CONCAT(",",BullseyeQueues!AA3,":",BullseyeQueues!AB3,":",BullseyeQueues!AC3,IF(ISBLANK(BullseyeQueues!AF3),"",_xlfn.CONCAT(",",BullseyeQueues!AF3,":",BullseyeQueues!AG3,":",BullseyeQueues!AH3,IF(ISBLANK(BullseyeQueues!AK3),"",_xlfn.CONCAT(",",BullseyeQueues!AK3,":",BullseyeQueues!AL3,":",BullseyeQueues!AM3)))))))))))) -> TIMEOUT_SECONDS:5:test 1,TIMEOUT_SECONDS:5:test 2|test 3,TIMEOUT_SECONDS:5:test 4 | I3: =_xlfn.CONCAT(IF(ISBLANK(BullseyeQueues!$O3),"",BullseyeQueues!$O3),IF(ISBLANK(BullseyeQueues!$P3),"",IF(ISBLANK(BullseyeQueues!$O3),BullseyeQueues!$P3,_xlfn.CONCAT(",",BullseyeQueues!$P3))),"|",IF(ISBLANK(BullseyeQueues!T3),"",BullseyeQueues!T3),IF(ISBLANK(BullseyeQueues!U3),"",IF(ISBLANK(BullseyeQueues!T3),BullseyeQueues!U3,_xlfn.CONCAT(",",BullseyeQueues!U3))),"|",IF(ISBLANK(BullseyeQueues!Y3),"",BullseyeQueues!Y3),IF(ISBLANK(BullseyeQueues!Z3),"",IF(ISBLANK(BullseyeQueues!Y3),BullseyeQueues!Z3,_xlfn.CONCAT(",",BullseyeQueues!Z3))),"|",IF(ISBLANK(BullseyeQueues!AD3),"",BullseyeQueues!AD3),IF(ISBLANK(BullseyeQueues!AE3),"",IF(ISBLANK(BullseyeQueues!AD3),BullseyeQueues!AE3,_xlfn.CONCAT(",",BullseyeQueues!AE3))),"|",IF(ISBLANK(BullseyeQueues!AI3),"",BullseyeQueues!AI3),IF(ISBLANK(BullseyeQueues!AJ3),"",IF(ISBLANK(BullseyeQueues!AI3),BullseyeQueues!AJ3,_xlfn.CONCAT(",",BullseyeQueues!AJ3))),"|",IF(ISBLANK(BullseyeQueues!AN3),"",BullseyeQueues!AN3),IF(ISBLANK(BullseyeQueues!AO3),"",IF(ISBLANK(BullseyeQueues!AN3),BullseyeQueues!AO3,_xlfn.CONCAT(",",BullseyeQueues!AO3)))) -> test 1 = 1:Home,bigTest1:none,bigTest2:none|test 1 = 2:Home,bigTest3:none,bigTest4:none|test 1 = 3:Home,bigTest5:none,bigTest6:none||| | J3: =BullseyeQueues!K3 -> BEST | K3: =BullseyeQueues!E3 -> 8005551234 | L3: =BullseyeQueues!F3 -> Company Name | M3: =BullseyeQueues!AP3 -> 8 | N3: =BullseyeQueues!AR3/100 -> 0.8 | O3: =BullseyeQueues!AS3*1000 -> 20000
